<?xml version="1.0"?>
<robot name="roll" xmlns:xacro="http://www.ros.org/wiki/xacro">



<xacro:property name="roll_radius" value="0.01" /> 
<xacro:property name="roll_height" value="0.12" />
<xacro:property name="roll_mass" value="0.01" /> <!-- in kg-->

<xacro:property name="base_x_origin_to_roll_origin" value="-0.080" />
<xacro:property name="base_y_origin_to_roll_origin" value="-0.060" />
<xacro:property name="base_z_origin_to_roll_origin" value="0.015" />


<xacro:macro name="cylinder_inertia" params="m r h">
<inertia  ixx="${m*(3*r*r+h*h)/12}" ixy = "0" ixz = "0"
iyy="${m*(3*r*r+h*h)/12}" iyz = "0"
izz="${m*r*r/2}" />
</xacro:macro>


<xacro:macro name="roll" params="parent">



<link name="roll_link">
<visual>
<origin xyz="0 0.06 0" rpy="${M_PI/2} 0 0" />
<geometry>
<!--<mesh filename="package://robot_pkg/dae/rolluse.dae"/>-->
<cylinder length="${roll_height}" radius="${roll_radius}" />
</geometry>
<material name="DarkGray" />
</visual>
<collision>
<origin xyz="0 0.06 0" rpy="${M_PI/2} 0 0" />
<geometry>
<!--<mesh filename="package://robot_pkg/dae/rolluse.dae"/>-->
<cylinder length="${roll_height}" radius="${roll_radius}" />
</geometry>
</collision>
<inertial>
<mass value="${roll_mass}" />
<origin xyz="0 0 0" />
<cylinder_inertia  m="${roll_mass}" r="${roll_radius}" h="${roll_height}" />
</inertial>
</link>

<!--


<link name="roll_link">
<visual>
<origin xyz="0 0 0" rpy="${M_PI/2} 0 0" />
<geometry>
<mesh filename="package://robot_pkg/dae/roll.dae"/>
</geometry>
<material name="DarkGray" />
</visual>
<collision>
<origin xyz="0 0 0" rpy="${M_PI/2} 0 0" />
<geometry>
<mesh filename="package://robot_pkg/dae/roll.dae"/>
</geometry>
</collision>
<inertial>
<mass value="${roll_mass}" />
<origin xyz="0 0 0" />
<cylinder_inertia  m="${roll_mass}" r="${roll_radius}" h="${roll_height}" />
</inertial>
</link>

-->

<joint name="roll_joint" type="continuous">
    <parent link="${parent}"/>
    <child link="roll_link"/>
    <origin xyz="${base_x_origin_to_roll_origin} ${base_y_origin_to_roll_origin} ${base_z_origin_to_roll_origin}" rpy="0 0 0" />
    <axis xyz="0 1 0" rpy="0 0 0" />
    <limit effort="100" velocity="10"/>
    <joint_properties damping="0" friction="0"/>
</joint>



<!--

<link name="box1_link">
<visual>
<origin xyz="0 0 0" rpy="0 0 0" />
<geometry>
<box size="0.002 0.002 0.002" />
</geometry>
<material name="DarkGray" />
</visual>
<collision>
<origin xyz="0 0 0" rpy="0 0 0" />
<geometry>
<box size="0.002 0.002 0.002" />
</geometry>
</collision>
<inertial>
<mass value="0.0001" />
<origin xyz="0 0 0" />
<box_inertia  m="0.0001" x="0.002" y="0.002" z="0.002"/>
</inertial>
</link>


<joint name="box1_joint" type="fixed">
    <parent link="roll_link"/>
    <child link="box1_link"/>
    <axis xyz="0 0 0" />
    <origin xyz="0 0.058 0.01" rpy="0 0 0" />
    <joint_properties damping="0" friction="0"/>
</joint>



<link name="box2_link">
<visual>
<origin xyz="0 0.002 0.0005" rpy="0 0 0" />
<geometry>
<box size="0.002 0.006 0.001" />
</geometry>
<material name="DarkGray" />
</visual>
<collision>
<origin xyz="0 0.002 0.0005" rpy="0 0 0" />
<geometry>
<box size="0.002 0.006 0.001" />
</geometry>
</collision>
<inertial>
<mass value="0.0001" />
<origin xyz="0 0 0" />
<box_inertia  m="0.0001" x="0.002" y="0.006" z="0.001"/>
</inertial>
</link>



<joint name="box2_joint" type="fixed">
    <parent link="box1_link"/>
    <child link="box2_link"/>
    <axis xyz="0 0 0" />
    <origin xyz="0 0 0.001" rpy="0 0 0" />
    <joint_properties damping="0" friction="0"/>
</joint>




<link name="box3_link">
<visual>
<origin xyz="0 0 -0.001" rpy="0 0 0" />
<geometry>
<box size="0.002 0.002 0.002" />
</geometry>
<material name="DarkGray" />
</visual>
<collision>
<origin xyz="0 0 -0.001" rpy="0 0 0" />
<geometry>
<box size="0.002 0.002 0.002" />
</geometry>
</collision>
<inertial>
<mass value="0.0001" />
<origin xyz="0 0 0" />
<box_inertia  m="0.0001" x="0.002" y="0.002" z="0.002"/>
</inertial>
</link>


<joint name="box3_joint" type="fixed">
    <parent link="box2_link"/>
    <child link="box3_link"/>
    <axis xyz="0 0 0" />
    <origin xyz="0 0.004 0" rpy="0 0 0" />
    <joint_properties damping="0" friction="0"/>
</joint>

-->

<!-- =========gazebo reference============ -->
<gazebo reference="roll_link">
<mu1 value="1.0"/>
<mu2 value="1.0"/>
<kp  value="10000000.0" />
<kd  value="1.0" />
<fdir1 value="1 0 0"/>
<material>Gazebo/White</material>
<turnGravityOff>false</turnGravityOff>
<selfCollide>true</selfCollide>
</gazebo>


<!-- Transmission is important to link the joints and the controller -->
<transmission name="roll_joint_trans">
<type>transmission_interface/SimpleTransmission</type>
<joint name="roll_joint">
<hardwareInterface>hardware_interface/VelocityJointInterface</hardwareInterface>
</joint>
<actuator name="roll_joint_motor">
<hardwareInterface>hardware_interface/VelocityJointInterface</hardwareInterface>
<mechanicalReduction>1</mechanicalReduction>
</actuator>
</transmission>

</xacro:macro>
</robot>
