<?xml version="1.0"?>
<robot name="wheel" xmlns:xacro="http://ros.org/wiki/xacro">

<!-- Wheels -->
<xacro:property name="wheel_radius" value="0.05" />
<xacro:property name="wheel_height" value="0.02" />
<xacro:property name="wheel_mass" value="0.2" /> <!-- in kg-->

<xacro:property name="base_x_origin_to_wheel_origin" value="0.000" />
<xacro:property name="base_y_origin_to_wheel_origin" value="0.100" />
<xacro:property name="base_z_origin_to_wheel_origin" value="0.0" />

<xacro:macro name="cylinder_inertia" params="m r h">
<inertia  ixx="${m*(3*r*r+h*h)/12}" ixy = "0" ixz = "0"
iyy="${m*(3*r*r+h*h)/12}" iyz = "0"
izz="${m*r*r/2}" />
</xacro:macro>

<xacro:macro name="wheel" params="fb lr parent translateX translateY flipY">
<!--fb : front, back ; lr: left, right -->
<link name="${fb}_${lr}_wheel_link">
<visual>
<origin xyz="0 0 0" rpy="${flipY*M_PI/2} 0 0" />
<geometry>
<mesh filename="package://robot_pkg/dae/wheel.dae"/>
</geometry>
<material name="DarkGray" />
</visual>
<collision>
<origin xyz="0 0 0" rpy="${flipY*M_PI/2} 0 0" />
<geometry>
<mesh filename="package://robot_pkg/dae/wheel.dae"/>
</geometry>
</collision>
<inertial>
<mass value="${wheel_mass}" />
<origin xyz="0 0 0" />
<cylinder_inertia  m="${wheel_mass}" r="${wheel_radius}" h="${wheel_height}" />
</inertial>
</link>

<joint name="${fb}_${lr}_wheel_joint" type="continuous">
    <parent link="${parent}"/>
    <child link="${fb}_${lr}_wheel_link"/>
    <origin xyz="${translateX * base_x_origin_to_wheel_origin} ${translateY * base_y_origin_to_wheel_origin} ${base_z_origin_to_wheel_origin}" rpy="0 0 0" />
    <axis xyz="0 1 0" rpy="0 0 0" />
    <limit effort="1000" velocity="100"/>
    <joint_properties damping="0.0" friction="0.0"/>
</joint>

<!-- =========gazebo reference============ -->
<gazebo reference="${fb}_${lr}_wheel_link">
<mu1 value="1.0"/>
<mu2 value="1.0"/>
<kp  value="10000000.0" />
<kd  value="1.0" />
<fdir1 value="1 0 0"/>
<material>Gazebo/White</material>
<turnGravityOff>false</turnGravityOff>
</gazebo>

<!-- Transmission is important to link the joints and the controller -->
<transmission name="${fb}_${lr}_wheel_joint_trans">
<type>transmission_interface/SimpleTransmission</type>
<joint name="${fb}_${lr}_wheel_joint">
<hardwareInterface>hardware_interface/EffortJointInterface</hardwareInterface>
</joint>
<actuator name="${fb}_${lr}_wheel_joint_motor">
<mechanicalReduction>1</mechanicalReduction>
</actuator>
</transmission>

</xacro:macro>
</robot>

